2020-08-11 18:21:11,508 ERROR: Exception on /api/login [POST] [in c:\users\1\inventory2\inventory1\venv\lib\site-packages\flask\app.py:1891]
Traceback (most recent call last):
  File "c:\users\1\inventory2\inventory1\venv\lib\site-packages\flask\app.py", line 2447, in wsgi_app
    response = self.full_dispatch_request()
  File "c:\users\1\inventory2\inventory1\venv\lib\site-packages\flask\app.py", line 1952, in full_dispatch_request
    rv = self.handle_user_exception(e)
  File "c:\users\1\inventory2\inventory1\venv\lib\site-packages\flask\app.py", line 1821, in handle_user_exception
    reraise(exc_type, exc_value, tb)
  File "c:\users\1\inventory2\inventory1\venv\lib\site-packages\flask\_compat.py", line 39, in reraise
    raise value
  File "c:\users\1\inventory2\inventory1\venv\lib\site-packages\flask\app.py", line 1950, in full_dispatch_request
    rv = self.dispatch_request()
  File "c:\users\1\inventory2\inventory1\venv\lib\site-packages\flask\app.py", line 1936, in dispatch_request
    return self.view_functions[rule.endpoint](**req.view_args)
  File "c:\users\1\inventory2\inventory1\venv\lib\site-packages\flask_cors\decorator.py", line 128, in wrapped_function
    resp = make_response(f(*args, **kwargs))
  File "c:\users\1\inventory2\inventory1\venv\lib\site-packages\flask_httpauth.py", line 163, in decorated
    return f(*args, **kwargs)
  File "C:\Users\1\inventory2\inventory1\app\api\tokens.py", line 13, in get_token
    token = g.current_user.get_token()
  File "C:\Users\1\inventory2\inventory1\app\models.py", line 133, in get_token
    self.token = base64.b64encode(os.random(24)).decode('utf-8')
AttributeError: module 'os' has no attribute 'random'
2020-08-11 18:22:28,230 INFO: Inventory1 startup [in C:\Users\1\inventory2\inventory1\app\__init__.py:42]
2020-08-11 18:22:36,145 ERROR: Exception on /api/login [POST] [in c:\users\1\inventory2\inventory1\venv\lib\site-packages\flask\app.py:1891]
Traceback (most recent call last):
  File "c:\users\1\inventory2\inventory1\venv\lib\site-packages\flask\app.py", line 2447, in wsgi_app
    response = self.full_dispatch_request()
  File "c:\users\1\inventory2\inventory1\venv\lib\site-packages\flask\app.py", line 1952, in full_dispatch_request
    rv = self.handle_user_exception(e)
  File "c:\users\1\inventory2\inventory1\venv\lib\site-packages\flask\app.py", line 1821, in handle_user_exception
    reraise(exc_type, exc_value, tb)
  File "c:\users\1\inventory2\inventory1\venv\lib\site-packages\flask\_compat.py", line 39, in reraise
    raise value
  File "c:\users\1\inventory2\inventory1\venv\lib\site-packages\flask\app.py", line 1950, in full_dispatch_request
    rv = self.dispatch_request()
  File "c:\users\1\inventory2\inventory1\venv\lib\site-packages\flask\app.py", line 1936, in dispatch_request
    return self.view_functions[rule.endpoint](**req.view_args)
  File "c:\users\1\inventory2\inventory1\venv\lib\site-packages\flask_cors\decorator.py", line 128, in wrapped_function
    resp = make_response(f(*args, **kwargs))
  File "c:\users\1\inventory2\inventory1\venv\lib\site-packages\flask_httpauth.py", line 163, in decorated
    return f(*args, **kwargs)
  File "C:\Users\1\inventory2\inventory1\app\api\tokens.py", line 13, in get_token
    token = g.current_user.get_token()
  File "C:\Users\1\inventory2\inventory1\app\models.py", line 134, in get_token
    self.token_expiration = now + timedelts(seconds=expires_in)
NameError: name 'timedelts' is not defined
2020-08-11 18:23:12,860 INFO: Inventory1 startup [in C:\Users\1\inventory2\inventory1\app\__init__.py:42]
2020-08-11 18:23:29,592 INFO: Inventory1 startup [in C:\Users\1\inventory2\inventory1\app\__init__.py:42]
2020-08-11 18:24:19,628 ERROR: Exception on /api/divisions [GET] [in c:\users\1\inventory2\inventory1\venv\lib\site-packages\flask\app.py:1891]
Traceback (most recent call last):
  File "c:\users\1\inventory2\inventory1\venv\lib\site-packages\flask\app.py", line 2447, in wsgi_app
    response = self.full_dispatch_request()
  File "c:\users\1\inventory2\inventory1\venv\lib\site-packages\flask\app.py", line 1952, in full_dispatch_request
    rv = self.handle_user_exception(e)
  File "c:\users\1\inventory2\inventory1\venv\lib\site-packages\flask\app.py", line 1821, in handle_user_exception
    reraise(exc_type, exc_value, tb)
  File "c:\users\1\inventory2\inventory1\venv\lib\site-packages\flask\_compat.py", line 39, in reraise
    raise value
  File "c:\users\1\inventory2\inventory1\venv\lib\site-packages\flask\app.py", line 1950, in full_dispatch_request
    rv = self.dispatch_request()
  File "c:\users\1\inventory2\inventory1\venv\lib\site-packages\flask\app.py", line 1936, in dispatch_request
    return self.view_functions[rule.endpoint](**req.view_args)
  File "c:\users\1\inventory2\inventory1\venv\lib\site-packages\flask_httpauth.py", line 148, in decorated
    user = self.authenticate(auth, password)
  File "c:\users\1\inventory2\inventory1\venv\lib\site-packages\flask_httpauth.py", line 347, in authenticate
    return self.verify_token_callback(token)
  File "C:\Users\1\inventory2\inventory1\app\api\auth.py", line 29, in verify_token
    g.current_user = Worker.check_token(token) if token else None
  File "C:\Users\1\inventory2\inventory1\app\models.py", line 147, in check_token
    worker = Worker.query.filter_by(token=toekn).first()
NameError: name 'toekn' is not defined
2020-08-11 21:26:48,106 INFO: Inventory1 startup [in C:\Users\1\inventory2\inventory1\app\__init__.py:42]
2020-08-11 21:27:06,012 INFO: Inventory1 startup [in C:\Users\1\inventory2\inventory1\app\__init__.py:42]
2020-08-11 21:27:15,995 INFO: Inventory1 startup [in C:\Users\1\inventory2\inventory1\app\__init__.py:42]
2020-08-11 21:27:26,665 INFO: Inventory1 startup [in C:\Users\1\inventory2\inventory1\app\__init__.py:42]
2020-08-11 21:27:33,692 INFO: Inventory1 startup [in C:\Users\1\inventory2\inventory1\app\__init__.py:42]
2020-08-11 21:27:38,692 INFO: Inventory1 startup [in C:\Users\1\inventory2\inventory1\app\__init__.py:42]
2020-08-11 21:27:42,760 INFO: Inventory1 startup [in C:\Users\1\inventory2\inventory1\app\__init__.py:42]
2020-08-11 21:27:52,562 INFO: Inventory1 startup [in C:\Users\1\inventory2\inventory1\app\__init__.py:42]
2020-08-11 21:29:34,777 INFO: Inventory1 startup [in C:\Users\1\inventory2\inventory1\app\__init__.py:42]
2020-08-11 21:29:49,985 INFO: Inventory1 startup [in C:\Users\1\inventory2\inventory1\app\__init__.py:42]
2020-08-11 21:30:25,474 ERROR: Exception on /api/operations [GET] [in c:\users\1\inventory2\inventory1\venv\lib\site-packages\flask\app.py:1891]
Traceback (most recent call last):
  File "c:\users\1\inventory2\inventory1\venv\lib\site-packages\flask\app.py", line 2447, in wsgi_app
    response = self.full_dispatch_request()
  File "c:\users\1\inventory2\inventory1\venv\lib\site-packages\flask\app.py", line 1952, in full_dispatch_request
    rv = self.handle_user_exception(e)
  File "c:\users\1\inventory2\inventory1\venv\lib\site-packages\flask\app.py", line 1821, in handle_user_exception
    reraise(exc_type, exc_value, tb)
  File "c:\users\1\inventory2\inventory1\venv\lib\site-packages\flask\_compat.py", line 39, in reraise
    raise value
  File "c:\users\1\inventory2\inventory1\venv\lib\site-packages\flask\app.py", line 1950, in full_dispatch_request
    rv = self.dispatch_request()
  File "c:\users\1\inventory2\inventory1\venv\lib\site-packages\flask\app.py", line 1936, in dispatch_request
    return self.view_functions[rule.endpoint](**req.view_args)
  File "c:\users\1\inventory2\inventory1\venv\lib\site-packages\flask_cors\decorator.py", line 128, in wrapped_function
    resp = make_response(f(*args, **kwargs))
  File "c:\users\1\inventory2\inventory1\venv\lib\site-packages\flask_httpauth.py", line 148, in decorated
    user = self.authenticate(auth, password)
  File "c:\users\1\inventory2\inventory1\venv\lib\site-packages\flask_httpauth.py", line 347, in authenticate
    return self.verify_token_callback(token)
  File "C:\Users\1\inventory2\inventory1\app\api\auth.py", line 29, in verify_token
    g.current_user = Worker.check_token(token) if token else None
  File "C:\Users\1\inventory2\inventory1\app\models.py", line 148, in check_token
    if worker is None or user.token_expiration < datetime.utcnow():
NameError: name 'user' is not defined
2020-08-11 21:34:12,184 INFO: Inventory1 startup [in C:\Users\1\inventory2\inventory1\app\__init__.py:42]
2020-08-11 21:34:16,215 ERROR: Exception on /api/operations [GET] [in c:\users\1\inventory2\inventory1\venv\lib\site-packages\flask\app.py:1891]
Traceback (most recent call last):
  File "c:\users\1\inventory2\inventory1\venv\lib\site-packages\flask\app.py", line 2447, in wsgi_app
    response = self.full_dispatch_request()
  File "c:\users\1\inventory2\inventory1\venv\lib\site-packages\flask\app.py", line 1952, in full_dispatch_request
    rv = self.handle_user_exception(e)
  File "c:\users\1\inventory2\inventory1\venv\lib\site-packages\flask\app.py", line 1821, in handle_user_exception
    reraise(exc_type, exc_value, tb)
  File "c:\users\1\inventory2\inventory1\venv\lib\site-packages\flask\_compat.py", line 39, in reraise
    raise value
  File "c:\users\1\inventory2\inventory1\venv\lib\site-packages\flask\app.py", line 1950, in full_dispatch_request
    rv = self.dispatch_request()
  File "c:\users\1\inventory2\inventory1\venv\lib\site-packages\flask\app.py", line 1936, in dispatch_request
    return self.view_functions[rule.endpoint](**req.view_args)
  File "c:\users\1\inventory2\inventory1\venv\lib\site-packages\flask_cors\decorator.py", line 128, in wrapped_function
    resp = make_response(f(*args, **kwargs))
  File "c:\users\1\inventory2\inventory1\venv\lib\site-packages\flask_httpauth.py", line 163, in decorated
    return f(*args, **kwargs)
  File "C:\Users\1\inventory2\inventory1\app\api\commodity.py", line 27, in get_operations
    operations = Operation.query.all()
NameError: name 'Operation' is not defined
2020-08-11 21:34:47,935 INFO: Inventory1 startup [in C:\Users\1\inventory2\inventory1\app\__init__.py:42]
