2020-07-31 23:18:41,631 ERROR: Exception on /api/object/a7a7e4e0-e986-4e65-b898-26308bb76a70/latest [GET] [in c:\users\1\inventory2\inventory1\venv\lib\site-packages\flask\app.py:1891]
Traceback (most recent call last):
  File "c:\users\1\inventory2\inventory1\venv\lib\site-packages\flask\app.py", line 2447, in wsgi_app
    response = self.full_dispatch_request()
  File "c:\users\1\inventory2\inventory1\venv\lib\site-packages\flask\app.py", line 1952, in full_dispatch_request
    rv = self.handle_user_exception(e)
  File "c:\users\1\inventory2\inventory1\venv\lib\site-packages\flask\app.py", line 1821, in handle_user_exception
    reraise(exc_type, exc_value, tb)
  File "c:\users\1\inventory2\inventory1\venv\lib\site-packages\flask\_compat.py", line 39, in reraise
    raise value
  File "c:\users\1\inventory2\inventory1\venv\lib\site-packages\flask\app.py", line 1950, in full_dispatch_request
    rv = self.dispatch_request()
  File "c:\users\1\inventory2\inventory1\venv\lib\site-packages\flask\app.py", line 1936, in dispatch_request
    return self.view_functions[rule.endpoint](**req.view_args)
  File "C:\Users\1\inventory2\inventory1\app\api\commodity.py", line 98, in get_latest_info_object
    "operation": objects_latest.operation_id,
AttributeError: 'Objects' object has no attribute 'operation_id'
2020-07-31 23:19:50,136 INFO: Inventory1 startup [in C:\Users\1\inventory2\inventory1\app\__init__.py:39]
2020-07-31 23:19:53,948 ERROR: Exception on /api/object/a7a7e4e0-e986-4e65-b898-26308bb76a70/latest [GET] [in c:\users\1\inventory2\inventory1\venv\lib\site-packages\flask\app.py:1891]
Traceback (most recent call last):
  File "c:\users\1\inventory2\inventory1\venv\lib\site-packages\flask\app.py", line 2447, in wsgi_app
    response = self.full_dispatch_request()
  File "c:\users\1\inventory2\inventory1\venv\lib\site-packages\flask\app.py", line 1952, in full_dispatch_request
    rv = self.handle_user_exception(e)
  File "c:\users\1\inventory2\inventory1\venv\lib\site-packages\flask\app.py", line 1821, in handle_user_exception
    reraise(exc_type, exc_value, tb)
  File "c:\users\1\inventory2\inventory1\venv\lib\site-packages\flask\_compat.py", line 39, in reraise
    raise value
  File "c:\users\1\inventory2\inventory1\venv\lib\site-packages\flask\app.py", line 1950, in full_dispatch_request
    rv = self.dispatch_request()
  File "c:\users\1\inventory2\inventory1\venv\lib\site-packages\flask\app.py", line 1936, in dispatch_request
    return self.view_functions[rule.endpoint](**req.view_args)
  File "C:\Users\1\inventory2\inventory1\app\api\commodity.py", line 95, in get_latest_info_object
    "name": objects_latest.Name,
AttributeError: 'Movement' object has no attribute 'Name'
2020-07-31 23:22:25,244 INFO: Inventory1 startup [in C:\Users\1\inventory2\inventory1\app\__init__.py:39]
2020-07-31 23:22:31,688 ERROR: Exception on /api/object/a7a7e4e0-e986-4e65-b898-26308bb76a70/latest [GET] [in c:\users\1\inventory2\inventory1\venv\lib\site-packages\flask\app.py:1891]
Traceback (most recent call last):
  File "c:\users\1\inventory2\inventory1\venv\lib\site-packages\flask\app.py", line 2447, in wsgi_app
    response = self.full_dispatch_request()
  File "c:\users\1\inventory2\inventory1\venv\lib\site-packages\flask\app.py", line 1952, in full_dispatch_request
    rv = self.handle_user_exception(e)
  File "c:\users\1\inventory2\inventory1\venv\lib\site-packages\flask\app.py", line 1821, in handle_user_exception
    reraise(exc_type, exc_value, tb)
  File "c:\users\1\inventory2\inventory1\venv\lib\site-packages\flask\_compat.py", line 39, in reraise
    raise value
  File "c:\users\1\inventory2\inventory1\venv\lib\site-packages\flask\app.py", line 1950, in full_dispatch_request
    rv = self.dispatch_request()
  File "c:\users\1\inventory2\inventory1\venv\lib\site-packages\flask\app.py", line 1936, in dispatch_request
    return self.view_functions[rule.endpoint](**req.view_args)
  File "C:\Users\1\inventory2\inventory1\app\api\commodity.py", line 95, in get_latest_info_object
    "name": objects_latest.Name,
AttributeError: 'Movement' object has no attribute 'Name'
2020-08-01 00:09:54,001 INFO: Inventory1 startup [in C:\Users\1\inventory2\inventory1\app\__init__.py:39]
2020-08-01 00:09:57,245 ERROR: Exception on /api/object/a7a7e4e0-e986-4e65-b898-26308bb76a70/latest [GET] [in c:\users\1\inventory2\inventory1\venv\lib\site-packages\flask\app.py:1891]
Traceback (most recent call last):
  File "c:\users\1\inventory2\inventory1\venv\lib\site-packages\flask\app.py", line 2447, in wsgi_app
    response = self.full_dispatch_request()
  File "c:\users\1\inventory2\inventory1\venv\lib\site-packages\flask\app.py", line 1952, in full_dispatch_request
    rv = self.handle_user_exception(e)
  File "c:\users\1\inventory2\inventory1\venv\lib\site-packages\flask\app.py", line 1821, in handle_user_exception
    reraise(exc_type, exc_value, tb)
  File "c:\users\1\inventory2\inventory1\venv\lib\site-packages\flask\_compat.py", line 39, in reraise
    raise value
  File "c:\users\1\inventory2\inventory1\venv\lib\site-packages\flask\app.py", line 1950, in full_dispatch_request
    rv = self.dispatch_request()
  File "c:\users\1\inventory2\inventory1\venv\lib\site-packages\flask\app.py", line 1936, in dispatch_request
    return self.view_functions[rule.endpoint](**req.view_args)
  File "C:\Users\1\inventory2\inventory1\app\api\commodity.py", line 95, in get_latest_info_object
    "name": objects_latest.object_Name,
AttributeError: 'Movement' object has no attribute 'object_Name'
2020-08-01 00:12:06,638 INFO: Inventory1 startup [in C:\Users\1\inventory2\inventory1\app\__init__.py:39]
2020-08-01 00:12:09,673 ERROR: Exception on /api/object/a7a7e4e0-e986-4e65-b898-26308bb76a70/latest [GET] [in c:\users\1\inventory2\inventory1\venv\lib\site-packages\flask\app.py:1891]
Traceback (most recent call last):
  File "c:\users\1\inventory2\inventory1\venv\lib\site-packages\flask\app.py", line 2447, in wsgi_app
    response = self.full_dispatch_request()
  File "c:\users\1\inventory2\inventory1\venv\lib\site-packages\flask\app.py", line 1952, in full_dispatch_request
    rv = self.handle_user_exception(e)
  File "c:\users\1\inventory2\inventory1\venv\lib\site-packages\flask\app.py", line 1821, in handle_user_exception
    reraise(exc_type, exc_value, tb)
  File "c:\users\1\inventory2\inventory1\venv\lib\site-packages\flask\_compat.py", line 39, in reraise
    raise value
  File "c:\users\1\inventory2\inventory1\venv\lib\site-packages\flask\app.py", line 1950, in full_dispatch_request
    rv = self.dispatch_request()
  File "c:\users\1\inventory2\inventory1\venv\lib\site-packages\flask\app.py", line 1936, in dispatch_request
    return self.view_functions[rule.endpoint](**req.view_args)
  File "C:\Users\1\inventory2\inventory1\app\api\commodity.py", line 98, in get_latest_info_object
    "operation": objects_latest.operation_id,
AttributeError: 'Objects' object has no attribute 'operation_id'
2020-08-01 00:13:58,577 INFO: Inventory1 startup [in C:\Users\1\inventory2\inventory1\app\__init__.py:39]
2020-08-01 00:14:14,567 INFO: Inventory1 startup [in C:\Users\1\inventory2\inventory1\app\__init__.py:39]
2020-08-01 00:14:19,376 ERROR: Exception on /api/object/a7a7e4e0-e986-4e65-b898-26308bb76a70/latest [GET] [in c:\users\1\inventory2\inventory1\venv\lib\site-packages\flask\app.py:1891]
Traceback (most recent call last):
  File "c:\users\1\inventory2\inventory1\venv\lib\site-packages\flask\app.py", line 2447, in wsgi_app
    response = self.full_dispatch_request()
  File "c:\users\1\inventory2\inventory1\venv\lib\site-packages\flask\app.py", line 1952, in full_dispatch_request
    rv = self.handle_user_exception(e)
  File "c:\users\1\inventory2\inventory1\venv\lib\site-packages\flask\app.py", line 1821, in handle_user_exception
    reraise(exc_type, exc_value, tb)
  File "c:\users\1\inventory2\inventory1\venv\lib\site-packages\flask\_compat.py", line 39, in reraise
    raise value
  File "c:\users\1\inventory2\inventory1\venv\lib\site-packages\flask\app.py", line 1950, in full_dispatch_request
    rv = self.dispatch_request()
  File "c:\users\1\inventory2\inventory1\venv\lib\site-packages\flask\app.py", line 1936, in dispatch_request
    return self.view_functions[rule.endpoint](**req.view_args)
  File "C:\Users\1\inventory2\inventory1\app\api\commodity.py", line 111, in get_latest_info_object
    return jsonify({'data': data})
  File "c:\users\1\inventory2\inventory1\venv\lib\site-packages\flask\json\__init__.py", line 370, in jsonify
    dumps(data, indent=indent, separators=separators) + "\n",
  File "c:\users\1\inventory2\inventory1\venv\lib\site-packages\flask\json\__init__.py", line 211, in dumps
    rv = _json.dumps(obj, **kwargs)
  File "C:\Users\1\AppData\Local\Programs\Python\Python38-32\lib\json\__init__.py", line 234, in dumps
    return cls(
  File "C:\Users\1\AppData\Local\Programs\Python\Python38-32\lib\json\encoder.py", line 199, in encode
    chunks = self.iterencode(o, _one_shot=True)
  File "C:\Users\1\AppData\Local\Programs\Python\Python38-32\lib\json\encoder.py", line 257, in iterencode
    return _iterencode(o, 0)
  File "c:\users\1\inventory2\inventory1\venv\lib\site-packages\flask\json\__init__.py", line 100, in default
    return _json.JSONEncoder.default(self, o)
  File "C:\Users\1\AppData\Local\Programs\Python\Python38-32\lib\json\encoder.py", line 179, in default
    raise TypeError(f'Object of type {o.__class__.__name__} '
TypeError: Object of type set is not JSON serializable
2020-08-01 00:15:16,999 INFO: Inventory1 startup [in C:\Users\1\inventory2\inventory1\app\__init__.py:39]
