2020-08-03 23:29:26,323 ERROR: Exception on /api/object/a7a7e4e0-e986-4e65-b898-26308bb76a70/latest [GET] [in c:\users\1\inventory2\inventory1\venv\lib\site-packages\flask\app.py:1891]
Traceback (most recent call last):
  File "c:\users\1\inventory2\inventory1\venv\lib\site-packages\flask\app.py", line 2447, in wsgi_app
    response = self.full_dispatch_request()
  File "c:\users\1\inventory2\inventory1\venv\lib\site-packages\flask\app.py", line 1952, in full_dispatch_request
    rv = self.handle_user_exception(e)
  File "c:\users\1\inventory2\inventory1\venv\lib\site-packages\flask\app.py", line 1821, in handle_user_exception
    reraise(exc_type, exc_value, tb)
  File "c:\users\1\inventory2\inventory1\venv\lib\site-packages\flask\_compat.py", line 39, in reraise
    raise value
  File "c:\users\1\inventory2\inventory1\venv\lib\site-packages\flask\app.py", line 1950, in full_dispatch_request
    rv = self.dispatch_request()
  File "c:\users\1\inventory2\inventory1\venv\lib\site-packages\flask\app.py", line 1936, in dispatch_request
    return self.view_functions[rule.endpoint](**req.view_args)
  File "C:\Users\1\inventory2\inventory1\app\api\commodity.py", line 100, in get_latest_info_object
    "object_id": objects_latest.oid,
AttributeError: 'result' object has no attribute 'oid'
2020-08-03 23:37:42,347 INFO: Inventory1 startup [in C:\Users\1\inventory2\inventory1\app\__init__.py:39]
2020-08-03 23:37:45,032 ERROR: Exception on /api/object/a7a7e4e0-e986-4e65-b898-26308bb76a70/latest [GET] [in c:\users\1\inventory2\inventory1\venv\lib\site-packages\flask\app.py:1891]
Traceback (most recent call last):
  File "c:\users\1\inventory2\inventory1\venv\lib\site-packages\flask\app.py", line 2447, in wsgi_app
    response = self.full_dispatch_request()
  File "c:\users\1\inventory2\inventory1\venv\lib\site-packages\flask\app.py", line 1952, in full_dispatch_request
    rv = self.handle_user_exception(e)
  File "c:\users\1\inventory2\inventory1\venv\lib\site-packages\flask\app.py", line 1821, in handle_user_exception
    reraise(exc_type, exc_value, tb)
  File "c:\users\1\inventory2\inventory1\venv\lib\site-packages\flask\_compat.py", line 39, in reraise
    raise value
  File "c:\users\1\inventory2\inventory1\venv\lib\site-packages\flask\app.py", line 1950, in full_dispatch_request
    rv = self.dispatch_request()
  File "c:\users\1\inventory2\inventory1\venv\lib\site-packages\flask\app.py", line 1936, in dispatch_request
    return self.view_functions[rule.endpoint](**req.view_args)
  File "C:\Users\1\inventory2\inventory1\app\api\commodity.py", line 100, in get_latest_info_object
    "object_id": objects_latest[0],
TypeError: 'ResultProxy' object is not subscriptable
2020-08-03 23:40:33,903 INFO: Inventory1 startup [in C:\Users\1\inventory2\inventory1\app\__init__.py:39]
2020-08-03 23:40:37,611 ERROR: Exception on /api/object/a7a7e4e0-e986-4e65-b898-26308bb76a70/latest [GET] [in c:\users\1\inventory2\inventory1\venv\lib\site-packages\flask\app.py:1891]
Traceback (most recent call last):
  File "c:\users\1\inventory2\inventory1\venv\lib\site-packages\flask\app.py", line 2447, in wsgi_app
    response = self.full_dispatch_request()
  File "c:\users\1\inventory2\inventory1\venv\lib\site-packages\flask\app.py", line 1952, in full_dispatch_request
    rv = self.handle_user_exception(e)
  File "c:\users\1\inventory2\inventory1\venv\lib\site-packages\flask\app.py", line 1821, in handle_user_exception
    reraise(exc_type, exc_value, tb)
  File "c:\users\1\inventory2\inventory1\venv\lib\site-packages\flask\_compat.py", line 39, in reraise
    raise value
  File "c:\users\1\inventory2\inventory1\venv\lib\site-packages\flask\app.py", line 1950, in full_dispatch_request
    rv = self.dispatch_request()
  File "c:\users\1\inventory2\inventory1\venv\lib\site-packages\flask\app.py", line 1936, in dispatch_request
    return self.view_functions[rule.endpoint](**req.view_args)
  File "C:\Users\1\inventory2\inventory1\app\api\commodity.py", line 100, in get_latest_info_object
    "object_id": objects_latest.items()[0],
AttributeError: 'ResultProxy' object has no attribute 'items'
2020-08-04 14:23:19,522 INFO: Inventory1 startup [in C:\Users\1\inventory2\inventory1\app\__init__.py:39]
2020-08-04 14:23:26,998 ERROR: Exception on /api/object/a7a7e4e0-e986-4e65-b898-26308bb76a70/latest [GET] [in c:\users\1\inventory2\inventory1\venv\lib\site-packages\flask\app.py:1891]
Traceback (most recent call last):
  File "c:\users\1\inventory2\inventory1\venv\lib\site-packages\flask\app.py", line 2447, in wsgi_app
    response = self.full_dispatch_request()
  File "c:\users\1\inventory2\inventory1\venv\lib\site-packages\flask\app.py", line 1952, in full_dispatch_request
    rv = self.handle_user_exception(e)
  File "c:\users\1\inventory2\inventory1\venv\lib\site-packages\flask\app.py", line 1821, in handle_user_exception
    reraise(exc_type, exc_value, tb)
  File "c:\users\1\inventory2\inventory1\venv\lib\site-packages\flask\_compat.py", line 39, in reraise
    raise value
  File "c:\users\1\inventory2\inventory1\venv\lib\site-packages\flask\app.py", line 1950, in full_dispatch_request
    rv = self.dispatch_request()
  File "c:\users\1\inventory2\inventory1\venv\lib\site-packages\flask\app.py", line 1936, in dispatch_request
    return self.view_functions[rule.endpoint](**req.view_args)
  File "C:\Users\1\inventory2\inventory1\app\api\commodity.py", line 115, in get_latest_info_object
    return jsonify({'data': data})
  File "c:\users\1\inventory2\inventory1\venv\lib\site-packages\flask\json\__init__.py", line 370, in jsonify
    dumps(data, indent=indent, separators=separators) + "\n",
  File "c:\users\1\inventory2\inventory1\venv\lib\site-packages\flask\json\__init__.py", line 211, in dumps
    rv = _json.dumps(obj, **kwargs)
  File "C:\Users\1\AppData\Local\Programs\Python\Python38-32\lib\json\__init__.py", line 234, in dumps
    return cls(
  File "C:\Users\1\AppData\Local\Programs\Python\Python38-32\lib\json\encoder.py", line 199, in encode
    chunks = self.iterencode(o, _one_shot=True)
  File "C:\Users\1\AppData\Local\Programs\Python\Python38-32\lib\json\encoder.py", line 257, in iterencode
    return _iterencode(o, 0)
  File "c:\users\1\inventory2\inventory1\venv\lib\site-packages\flask\json\__init__.py", line 100, in default
    return _json.JSONEncoder.default(self, o)
  File "C:\Users\1\AppData\Local\Programs\Python\Python38-32\lib\json\encoder.py", line 179, in default
    raise TypeError(f'Object of type {o.__class__.__name__} '
TypeError: Object of type RowProxy is not JSON serializable
2020-08-04 14:24:41,171 INFO: Inventory1 startup [in C:\Users\1\inventory2\inventory1\app\__init__.py:39]
2020-08-04 14:31:51,524 INFO: Inventory1 startup [in C:\Users\1\inventory2\inventory1\app\__init__.py:39]
2020-08-04 14:59:33,303 INFO: Inventory1 startup [in C:\Users\1\inventory2\inventory1\app\__init__.py:39]
2020-08-04 15:04:43,523 INFO: Inventory1 startup [in C:\Users\1\inventory2\inventory1\app\__init__.py:39]
2020-08-04 15:11:36,616 INFO: Inventory1 startup [in C:\Users\1\inventory2\inventory1\app\__init__.py:39]
2020-08-04 15:12:33,896 INFO: Inventory1 startup [in C:\Users\1\inventory2\inventory1\app\__init__.py:39]
2020-08-04 15:14:25,192 INFO: Inventory1 startup [in C:\Users\1\inventory2\inventory1\app\__init__.py:39]
2020-08-04 15:15:37,761 INFO: Inventory1 startup [in C:\Users\1\inventory2\inventory1\app\__init__.py:39]
2020-08-04 15:47:42,147 INFO: Inventory1 startup [in C:\Users\1\inventory2\inventory1\app\__init__.py:39]
2020-08-04 15:53:04,010 INFO: Inventory1 startup [in C:\Users\1\inventory2\inventory1\app\__init__.py:39]
2020-08-04 15:54:12,390 INFO: Inventory1 startup [in C:\Users\1\inventory2\inventory1\app\__init__.py:39]
2020-08-04 15:54:40,785 INFO: Inventory1 startup [in C:\Users\1\inventory2\inventory1\app\__init__.py:39]
2020-08-04 15:54:49,501 ERROR: Exception on /api/object/new [POST] [in c:\users\1\inventory2\inventory1\venv\lib\site-packages\flask\app.py:1891]
Traceback (most recent call last):
  File "c:\users\1\inventory2\inventory1\venv\lib\site-packages\flask\app.py", line 2447, in wsgi_app
    response = self.full_dispatch_request()
  File "c:\users\1\inventory2\inventory1\venv\lib\site-packages\flask\app.py", line 1952, in full_dispatch_request
    rv = self.handle_user_exception(e)
  File "c:\users\1\inventory2\inventory1\venv\lib\site-packages\flask\app.py", line 1821, in handle_user_exception
    reraise(exc_type, exc_value, tb)
  File "c:\users\1\inventory2\inventory1\venv\lib\site-packages\flask\_compat.py", line 39, in reraise
    raise value
  File "c:\users\1\inventory2\inventory1\venv\lib\site-packages\flask\app.py", line 1950, in full_dispatch_request
    rv = self.dispatch_request()
  File "c:\users\1\inventory2\inventory1\venv\lib\site-packages\flask\app.py", line 1936, in dispatch_request
    return self.view_functions[rule.endpoint](**req.view_args)
TypeError: decorator() missing 1 required positional argument: 'f'
2020-08-04 15:56:57,161 INFO: Inventory1 startup [in C:\Users\1\inventory2\inventory1\app\__init__.py:39]
