2020-08-01 00:15:19,813 ERROR: Exception on /api/object/a7a7e4e0-e986-4e65-b898-26308bb76a70/latest [GET] [in c:\users\1\inventory2\inventory1\venv\lib\site-packages\flask\app.py:1891]
Traceback (most recent call last):
  File "c:\users\1\inventory2\inventory1\venv\lib\site-packages\flask\app.py", line 2447, in wsgi_app
    response = self.full_dispatch_request()
  File "c:\users\1\inventory2\inventory1\venv\lib\site-packages\flask\app.py", line 1952, in full_dispatch_request
    rv = self.handle_user_exception(e)
  File "c:\users\1\inventory2\inventory1\venv\lib\site-packages\flask\app.py", line 1821, in handle_user_exception
    reraise(exc_type, exc_value, tb)
  File "c:\users\1\inventory2\inventory1\venv\lib\site-packages\flask\_compat.py", line 39, in reraise
    raise value
  File "c:\users\1\inventory2\inventory1\venv\lib\site-packages\flask\app.py", line 1950, in full_dispatch_request
    rv = self.dispatch_request()
  File "c:\users\1\inventory2\inventory1\venv\lib\site-packages\flask\app.py", line 1936, in dispatch_request
    return self.view_functions[rule.endpoint](**req.view_args)
  File "C:\Users\1\inventory2\inventory1\app\api\commodity.py", line 107, in get_latest_info_object
    objects_latest.operation_id
AttributeError: 'Objects' object has no attribute 'operation_id'
2020-08-01 00:16:25,485 INFO: Inventory1 startup [in C:\Users\1\inventory2\inventory1\app\__init__.py:39]
2020-08-01 00:16:27,836 ERROR: Exception on /api/object/a7a7e4e0-e986-4e65-b898-26308bb76a70/latest [GET] [in c:\users\1\inventory2\inventory1\venv\lib\site-packages\flask\app.py:1891]
Traceback (most recent call last):
  File "c:\users\1\inventory2\inventory1\venv\lib\site-packages\flask\app.py", line 2447, in wsgi_app
    response = self.full_dispatch_request()
  File "c:\users\1\inventory2\inventory1\venv\lib\site-packages\flask\app.py", line 1952, in full_dispatch_request
    rv = self.handle_user_exception(e)
  File "c:\users\1\inventory2\inventory1\venv\lib\site-packages\flask\app.py", line 1821, in handle_user_exception
    reraise(exc_type, exc_value, tb)
  File "c:\users\1\inventory2\inventory1\venv\lib\site-packages\flask\_compat.py", line 39, in reraise
    raise value
  File "c:\users\1\inventory2\inventory1\venv\lib\site-packages\flask\app.py", line 1950, in full_dispatch_request
    rv = self.dispatch_request()
  File "c:\users\1\inventory2\inventory1\venv\lib\site-packages\flask\app.py", line 1936, in dispatch_request
    return self.view_functions[rule.endpoint](**req.view_args)
  File "C:\Users\1\inventory2\inventory1\app\api\commodity.py", line 107, in get_latest_info_object
    objects_latest.operation_id
AttributeError: 'Objects' object has no attribute 'operation_id'
2020-08-01 00:17:34,146 INFO: Inventory1 startup [in C:\Users\1\inventory2\inventory1\app\__init__.py:39]
2020-08-01 00:17:36,084 ERROR: Exception on /api/object/a7a7e4e0-e986-4e65-b898-26308bb76a70/latest [GET] [in c:\users\1\inventory2\inventory1\venv\lib\site-packages\flask\app.py:1891]
Traceback (most recent call last):
  File "c:\users\1\inventory2\inventory1\venv\lib\site-packages\flask\app.py", line 2447, in wsgi_app
    response = self.full_dispatch_request()
  File "c:\users\1\inventory2\inventory1\venv\lib\site-packages\flask\app.py", line 1952, in full_dispatch_request
    rv = self.handle_user_exception(e)
  File "c:\users\1\inventory2\inventory1\venv\lib\site-packages\flask\app.py", line 1821, in handle_user_exception
    reraise(exc_type, exc_value, tb)
  File "c:\users\1\inventory2\inventory1\venv\lib\site-packages\flask\_compat.py", line 39, in reraise
    raise value
  File "c:\users\1\inventory2\inventory1\venv\lib\site-packages\flask\app.py", line 1950, in full_dispatch_request
    rv = self.dispatch_request()
  File "c:\users\1\inventory2\inventory1\venv\lib\site-packages\flask\app.py", line 1936, in dispatch_request
    return self.view_functions[rule.endpoint](**req.view_args)
  File "C:\Users\1\inventory2\inventory1\app\api\commodity.py", line 107, in get_latest_info_object
    typeof(objects_latest)
NameError: name 'typeof' is not defined
2020-08-01 00:19:08,694 INFO: Inventory1 startup [in C:\Users\1\inventory2\inventory1\app\__init__.py:39]
2020-08-01 00:19:11,969 ERROR: Exception on /api/object/a7a7e4e0-e986-4e65-b898-26308bb76a70/latest [GET] [in c:\users\1\inventory2\inventory1\venv\lib\site-packages\flask\app.py:1891]
Traceback (most recent call last):
  File "c:\users\1\inventory2\inventory1\venv\lib\site-packages\flask\app.py", line 2447, in wsgi_app
    response = self.full_dispatch_request()
  File "c:\users\1\inventory2\inventory1\venv\lib\site-packages\flask\app.py", line 1952, in full_dispatch_request
    rv = self.handle_user_exception(e)
  File "c:\users\1\inventory2\inventory1\venv\lib\site-packages\flask\app.py", line 1821, in handle_user_exception
    reraise(exc_type, exc_value, tb)
  File "c:\users\1\inventory2\inventory1\venv\lib\site-packages\flask\_compat.py", line 39, in reraise
    raise value
  File "c:\users\1\inventory2\inventory1\venv\lib\site-packages\flask\app.py", line 1950, in full_dispatch_request
    rv = self.dispatch_request()
  File "c:\users\1\inventory2\inventory1\venv\lib\site-packages\flask\app.py", line 1936, in dispatch_request
    return self.view_functions[rule.endpoint](**req.view_args)
  File "C:\Users\1\inventory2\inventory1\app\api\commodity.py", line 98, in get_latest_info_object
    "operation": objects_latest.operation_id,
AttributeError: 'Objects' object has no attribute 'operation_id'
2020-08-01 00:19:58,087 INFO: Inventory1 startup [in C:\Users\1\inventory2\inventory1\app\__init__.py:39]
2020-08-01 00:20:00,944 ERROR: Exception on /api/object/a7a7e4e0-e986-4e65-b898-26308bb76a70/latest [GET] [in c:\users\1\inventory2\inventory1\venv\lib\site-packages\flask\app.py:1891]
Traceback (most recent call last):
  File "c:\users\1\inventory2\inventory1\venv\lib\site-packages\flask\app.py", line 2447, in wsgi_app
    response = self.full_dispatch_request()
  File "c:\users\1\inventory2\inventory1\venv\lib\site-packages\flask\app.py", line 1952, in full_dispatch_request
    rv = self.handle_user_exception(e)
  File "c:\users\1\inventory2\inventory1\venv\lib\site-packages\flask\app.py", line 1821, in handle_user_exception
    reraise(exc_type, exc_value, tb)
  File "c:\users\1\inventory2\inventory1\venv\lib\site-packages\flask\_compat.py", line 39, in reraise
    raise value
  File "c:\users\1\inventory2\inventory1\venv\lib\site-packages\flask\app.py", line 1950, in full_dispatch_request
    rv = self.dispatch_request()
  File "c:\users\1\inventory2\inventory1\venv\lib\site-packages\flask\app.py", line 1936, in dispatch_request
    return self.view_functions[rule.endpoint](**req.view_args)
  File "C:\Users\1\inventory2\inventory1\app\api\commodity.py", line 92, in get_latest_info_object
    objects_latest = db.session.query(Objects, Operations).join(Movements).join(Divisions, Divisions.division_id == Movements.division_id).join(Placements).filter(Objects.oid == oid).order_by(Movements.operation_date.desc()).first()
  File "c:\users\1\inventory2\inventory1\venv\lib\site-packages\sqlalchemy\orm\query.py", line 2372, in join
    return self._join(
  File "<string>", line 2, in _join
  File "c:\users\1\inventory2\inventory1\venv\lib\site-packages\sqlalchemy\orm\base.py", line 227, in generate
    fn(self, *args[1:], **kw)
  File "c:\users\1\inventory2\inventory1\venv\lib\site-packages\sqlalchemy\orm\query.py", line 2555, in _join
    self._join_left_to_right(
  File "c:\users\1\inventory2\inventory1\venv\lib\site-packages\sqlalchemy\orm\query.py", line 2579, in _join_left_to_right
    ) = self._join_determine_implicit_left_side(left, right, onclause)
  File "c:\users\1\inventory2\inventory1\venv\lib\site-packages\sqlalchemy\orm\query.py", line 2715, in _join_determine_implicit_left_side
    raise sa_exc.InvalidRequestError(
sqlalchemy.exc.InvalidRequestError: Can't determine which FROM clause to join from, there are multiple FROMS which can join to this entity. Please use the .select_from() method to establish an explicit left side, as well as providing an explcit ON clause if not present already to help resolve the ambiguity.
2020-08-01 00:27:05,547 INFO: Inventory1 startup [in C:\Users\1\inventory2\inventory1\app\__init__.py:39]
2020-08-01 00:27:17,322 ERROR: Exception on /api/object/a7a7e4e0-e986-4e65-b898-26308bb76a70/latest [GET] [in c:\users\1\inventory2\inventory1\venv\lib\site-packages\flask\app.py:1891]
Traceback (most recent call last):
  File "c:\users\1\inventory2\inventory1\venv\lib\site-packages\flask\app.py", line 2447, in wsgi_app
    response = self.full_dispatch_request()
  File "c:\users\1\inventory2\inventory1\venv\lib\site-packages\flask\app.py", line 1952, in full_dispatch_request
    rv = self.handle_user_exception(e)
  File "c:\users\1\inventory2\inventory1\venv\lib\site-packages\flask\app.py", line 1821, in handle_user_exception
    reraise(exc_type, exc_value, tb)
  File "c:\users\1\inventory2\inventory1\venv\lib\site-packages\flask\_compat.py", line 39, in reraise
    raise value
  File "c:\users\1\inventory2\inventory1\venv\lib\site-packages\flask\app.py", line 1950, in full_dispatch_request
    rv = self.dispatch_request()
  File "c:\users\1\inventory2\inventory1\venv\lib\site-packages\flask\app.py", line 1936, in dispatch_request
    return self.view_functions[rule.endpoint](**req.view_args)
  File "C:\Users\1\inventory2\inventory1\app\api\commodity.py", line 99, in get_latest_info_object
    "object_id": objects_latest.oid,
NameError: name 'objects_latest' is not defined
2020-08-01 00:27:50,334 INFO: Inventory1 startup [in C:\Users\1\inventory2\inventory1\app\__init__.py:39]
