2020-08-20 15:36:06,233 ERROR: Exception on /api/object [POST] [in c:\users\1\inventory2\inventory1\venv\lib\site-packages\flask\app.py:1891]
Traceback (most recent call last):
  File "c:\users\1\inventory2\inventory1\venv\lib\site-packages\flask\app.py", line 2447, in wsgi_app
    response = self.full_dispatch_request()
  File "c:\users\1\inventory2\inventory1\venv\lib\site-packages\flask\app.py", line 1952, in full_dispatch_request
    rv = self.handle_user_exception(e)
  File "c:\users\1\inventory2\inventory1\venv\lib\site-packages\flask\app.py", line 1821, in handle_user_exception
    reraise(exc_type, exc_value, tb)
  File "c:\users\1\inventory2\inventory1\venv\lib\site-packages\flask\_compat.py", line 39, in reraise
    raise value
  File "c:\users\1\inventory2\inventory1\venv\lib\site-packages\flask\app.py", line 1950, in full_dispatch_request
    rv = self.dispatch_request()
  File "c:\users\1\inventory2\inventory1\venv\lib\site-packages\flask\app.py", line 1936, in dispatch_request
    return self.view_functions[rule.endpoint](**req.view_args)
  File "c:\users\1\inventory2\inventory1\venv\lib\site-packages\flask_httpauth.py", line 163, in decorated
    return f(*args, **kwargs)
  File "c:\users\1\inventory2\inventory1\venv\lib\site-packages\flask_cors\decorator.py", line 128, in wrapped_function
    resp = make_response(f(*args, **kwargs))
  File "C:\Users\1\inventory2\inventory1\app\api\commodity.py", line 275, in object_change_location
    movement = Movement(oid = the_object, operation_id=Operation.query.filter_by(name=row['operation']).first().id, placement_id =Placement.query.filter_by(placement_name=row['placement']).first().id, description=row['movement'], operation_time=datetime.datetime.strptime(row['date'],  '%Y-%m-%d %H:%M:%S'), asinfo=row['movement_info'])
  File "C:\Users\1\AppData\Local\Programs\Python\Python38-32\lib\_strptime.py", line 568, in _strptime_datetime
    tt, fraction, gmtoff_fraction = _strptime(data_string, format)
  File "C:\Users\1\AppData\Local\Programs\Python\Python38-32\lib\_strptime.py", line 349, in _strptime
    raise ValueError("time data %r does not match format %r" %
ValueError: time data '2020-08-20T08:36:05.742Z' does not match format '%Y-%m-%d %H:%M:%S'
2020-08-20 15:37:13,437 ERROR: Exception on /api/report/motion [POST] [in c:\users\1\inventory2\inventory1\venv\lib\site-packages\flask\app.py:1891]
Traceback (most recent call last):
  File "c:\users\1\inventory2\inventory1\venv\lib\site-packages\flask\app.py", line 2447, in wsgi_app
    response = self.full_dispatch_request()
  File "c:\users\1\inventory2\inventory1\venv\lib\site-packages\flask\app.py", line 1952, in full_dispatch_request
    rv = self.handle_user_exception(e)
  File "c:\users\1\inventory2\inventory1\venv\lib\site-packages\flask\app.py", line 1821, in handle_user_exception
    reraise(exc_type, exc_value, tb)
  File "c:\users\1\inventory2\inventory1\venv\lib\site-packages\flask\_compat.py", line 39, in reraise
    raise value
  File "c:\users\1\inventory2\inventory1\venv\lib\site-packages\flask\app.py", line 1950, in full_dispatch_request
    rv = self.dispatch_request()
  File "c:\users\1\inventory2\inventory1\venv\lib\site-packages\flask\app.py", line 1936, in dispatch_request
    return self.view_functions[rule.endpoint](**req.view_args)
  File "c:\users\1\inventory2\inventory1\venv\lib\site-packages\flask_httpauth.py", line 163, in decorated
    return f(*args, **kwargs)
  File "c:\users\1\inventory2\inventory1\venv\lib\site-packages\flask_cors\decorator.py", line 128, in wrapped_function
    resp = make_response(f(*args, **kwargs))
  File "C:\Users\1\inventory2\inventory1\app\api\commodity.py", line 233, in get_report_motion
    data =  [{
  File "C:\Users\1\inventory2\inventory1\app\api\commodity.py", line 237, in <listcomp>
    "previous_placement":   Placement.query.get(object_report.from_placement_id).placement_name,
AttributeError: 'NoneType' object has no attribute 'placement_name'
2020-08-20 15:37:45,413 INFO: Inventory1 startup [in C:\Users\1\inventory2\inventory1\app\__init__.py:42]
2020-08-20 15:39:41,601 ERROR: Exception on /api/placement/undefined [GET] [in c:\users\1\inventory2\inventory1\venv\lib\site-packages\flask\app.py:1891]
Traceback (most recent call last):
  File "c:\users\1\inventory2\inventory1\venv\lib\site-packages\flask\app.py", line 2447, in wsgi_app
    response = self.full_dispatch_request()
  File "c:\users\1\inventory2\inventory1\venv\lib\site-packages\flask\app.py", line 1952, in full_dispatch_request
    rv = self.handle_user_exception(e)
  File "c:\users\1\inventory2\inventory1\venv\lib\site-packages\flask\app.py", line 1821, in handle_user_exception
    reraise(exc_type, exc_value, tb)
  File "c:\users\1\inventory2\inventory1\venv\lib\site-packages\flask\_compat.py", line 39, in reraise
    raise value
  File "c:\users\1\inventory2\inventory1\venv\lib\site-packages\flask\app.py", line 1950, in full_dispatch_request
    rv = self.dispatch_request()
  File "c:\users\1\inventory2\inventory1\venv\lib\site-packages\flask\app.py", line 1936, in dispatch_request
    return self.view_functions[rule.endpoint](**req.view_args)
  File "c:\users\1\inventory2\inventory1\venv\lib\site-packages\flask_httpauth.py", line 163, in decorated
    return f(*args, **kwargs)
  File "c:\users\1\inventory2\inventory1\venv\lib\site-packages\flask_cors\decorator.py", line 128, in wrapped_function
    resp = make_response(f(*args, **kwargs))
  File "C:\Users\1\inventory2\inventory1\app\api\commodity.py", line 61, in placements
    placements = Division.query.filter_by(division_name=division).first().placements.all()
AttributeError: 'NoneType' object has no attribute 'placements'
2020-08-20 15:42:42,945 ERROR: Exception on /api/object/find [POST] [in c:\users\1\inventory2\inventory1\venv\lib\site-packages\flask\app.py:1891]
Traceback (most recent call last):
  File "c:\users\1\inventory2\inventory1\venv\lib\site-packages\flask\app.py", line 2447, in wsgi_app
    response = self.full_dispatch_request()
  File "c:\users\1\inventory2\inventory1\venv\lib\site-packages\flask\app.py", line 1952, in full_dispatch_request
    rv = self.handle_user_exception(e)
  File "c:\users\1\inventory2\inventory1\venv\lib\site-packages\flask\app.py", line 1821, in handle_user_exception
    reraise(exc_type, exc_value, tb)
  File "c:\users\1\inventory2\inventory1\venv\lib\site-packages\flask\_compat.py", line 39, in reraise
    raise value
  File "c:\users\1\inventory2\inventory1\venv\lib\site-packages\flask\app.py", line 1950, in full_dispatch_request
    rv = self.dispatch_request()
  File "c:\users\1\inventory2\inventory1\venv\lib\site-packages\flask\app.py", line 1936, in dispatch_request
    return self.view_functions[rule.endpoint](**req.view_args)
  File "c:\users\1\inventory2\inventory1\venv\lib\site-packages\flask_cors\decorator.py", line 128, in wrapped_function
    resp = make_response(f(*args, **kwargs))
  File "C:\Users\1\inventory2\inventory1\app\api\commodity.py", line 146, in get_objects
    if row['barcode']!="":
KeyError: 'barcode'
2020-08-20 15:48:32,192 INFO: Inventory1 startup [in C:\Users\1\inventory2\inventory1\app\__init__.py:42]
2020-08-20 15:48:37,906 INFO: Inventory1 startup [in C:\Users\1\inventory2\inventory1\app\__init__.py:42]
2020-08-20 15:48:50,475 ERROR: Exception on /api/object/find [POST] [in c:\users\1\inventory2\inventory1\venv\lib\site-packages\flask\app.py:1891]
Traceback (most recent call last):
  File "c:\users\1\inventory2\inventory1\venv\lib\site-packages\flask\app.py", line 2447, in wsgi_app
    response = self.full_dispatch_request()
  File "c:\users\1\inventory2\inventory1\venv\lib\site-packages\flask\app.py", line 1952, in full_dispatch_request
    rv = self.handle_user_exception(e)
  File "c:\users\1\inventory2\inventory1\venv\lib\site-packages\flask\app.py", line 1821, in handle_user_exception
    reraise(exc_type, exc_value, tb)
  File "c:\users\1\inventory2\inventory1\venv\lib\site-packages\flask\_compat.py", line 39, in reraise
    raise value
  File "c:\users\1\inventory2\inventory1\venv\lib\site-packages\flask\app.py", line 1950, in full_dispatch_request
    rv = self.dispatch_request()
  File "c:\users\1\inventory2\inventory1\venv\lib\site-packages\flask\app.py", line 1936, in dispatch_request
    return self.view_functions[rule.endpoint](**req.view_args)
  File "c:\users\1\inventory2\inventory1\venv\lib\site-packages\flask_cors\decorator.py", line 128, in wrapped_function
    resp = make_response(f(*args, **kwargs))
  File "C:\Users\1\inventory2\inventory1\app\api\commodity.py", line 206, in get_objects
    data = [{
  File "C:\Users\1\inventory2\inventory1\app\api\commodity.py", line 211, in <listcomp>
    'division': Division.query.filter_by(id=Placement.query.filter_by(id=4).first().division_id).first().id,
AttributeError: 'NoneType' object has no attribute 'division_id'
2020-08-20 15:54:20,582 INFO: Inventory1 startup [in C:\Users\1\inventory2\inventory1\app\__init__.py:42]
