2020-08-11 17:44:36,008 ERROR: Exception on /api/divisions [GET] [in c:\users\1\inventory2\inventory1\venv\lib\site-packages\flask\app.py:1891]
Traceback (most recent call last):
  File "c:\users\1\inventory2\inventory1\venv\lib\site-packages\flask\app.py", line 2447, in wsgi_app
    response = self.full_dispatch_request()
  File "c:\users\1\inventory2\inventory1\venv\lib\site-packages\flask\app.py", line 1952, in full_dispatch_request
    rv = self.handle_user_exception(e)
  File "c:\users\1\inventory2\inventory1\venv\lib\site-packages\flask\app.py", line 1821, in handle_user_exception
    reraise(exc_type, exc_value, tb)
  File "c:\users\1\inventory2\inventory1\venv\lib\site-packages\flask\_compat.py", line 39, in reraise
    raise value
  File "c:\users\1\inventory2\inventory1\venv\lib\site-packages\flask\app.py", line 1950, in full_dispatch_request
    rv = self.dispatch_request()
  File "c:\users\1\inventory2\inventory1\venv\lib\site-packages\flask\app.py", line 1936, in dispatch_request
    return self.view_functions[rule.endpoint](**req.view_args)
  File "c:\users\1\inventory2\inventory1\venv\lib\site-packages\flask_httpauth.py", line 163, in decorated
    return f(*args, **kwargs)
  File "c:\users\1\inventory2\inventory1\venv\lib\site-packages\flask_cors\decorator.py", line 128, in wrapped_function
    resp = make_response(f(*args, **kwargs))
  File "c:\users\1\inventory2\inventory1\venv\lib\site-packages\flask\helpers.py", line 223, in make_response
    return current_app.make_response(args)
  File "c:\users\1\inventory2\inventory1\venv\lib\site-packages\flask\app.py", line 2097, in make_response
    raise TypeError(
TypeError: The view function did not return a valid response. The function either returned None or ended without a return statement.
2020-08-11 17:45:27,436 ERROR: Exception on /api/divisions [GET] [in c:\users\1\inventory2\inventory1\venv\lib\site-packages\flask\app.py:1891]
Traceback (most recent call last):
  File "c:\users\1\inventory2\inventory1\venv\lib\site-packages\flask\app.py", line 2447, in wsgi_app
    response = self.full_dispatch_request()
  File "c:\users\1\inventory2\inventory1\venv\lib\site-packages\flask\app.py", line 1952, in full_dispatch_request
    rv = self.handle_user_exception(e)
  File "c:\users\1\inventory2\inventory1\venv\lib\site-packages\flask\app.py", line 1821, in handle_user_exception
    reraise(exc_type, exc_value, tb)
  File "c:\users\1\inventory2\inventory1\venv\lib\site-packages\flask\_compat.py", line 39, in reraise
    raise value
  File "c:\users\1\inventory2\inventory1\venv\lib\site-packages\flask\app.py", line 1950, in full_dispatch_request
    rv = self.dispatch_request()
  File "c:\users\1\inventory2\inventory1\venv\lib\site-packages\flask\app.py", line 1936, in dispatch_request
    return self.view_functions[rule.endpoint](**req.view_args)
  File "c:\users\1\inventory2\inventory1\venv\lib\site-packages\flask_httpauth.py", line 163, in decorated
    return f(*args, **kwargs)
  File "c:\users\1\inventory2\inventory1\venv\lib\site-packages\flask_cors\decorator.py", line 128, in wrapped_function
    resp = make_response(f(*args, **kwargs))
  File "c:\users\1\inventory2\inventory1\venv\lib\site-packages\flask\helpers.py", line 223, in make_response
    return current_app.make_response(args)
  File "c:\users\1\inventory2\inventory1\venv\lib\site-packages\flask\app.py", line 2097, in make_response
    raise TypeError(
TypeError: The view function did not return a valid response. The function either returned None or ended without a return statement.
2020-08-11 18:03:15,182 INFO: Inventory1 startup [in C:\Users\1\inventory2\inventory1\app\__init__.py:42]
2020-08-11 18:03:41,414 INFO: Inventory1 startup [in C:\Users\1\inventory2\inventory1\app\__init__.py:42]
2020-08-11 18:03:52,097 INFO: Inventory1 startup [in C:\Users\1\inventory2\inventory1\app\__init__.py:42]
2020-08-11 18:04:12,251 INFO: Inventory1 startup [in C:\Users\1\inventory2\inventory1\app\__init__.py:42]
2020-08-11 18:04:52,198 INFO: Inventory1 startup [in C:\Users\1\inventory2\inventory1\app\__init__.py:42]
2020-08-11 18:05:08,199 INFO: Inventory1 startup [in C:\Users\1\inventory2\inventory1\app\__init__.py:42]
2020-08-11 18:05:18,444 INFO: Inventory1 startup [in C:\Users\1\inventory2\inventory1\app\__init__.py:42]
2020-08-11 18:10:40,705 INFO: Inventory1 startup [in C:\Users\1\inventory2\inventory1\app\__init__.py:42]
2020-08-11 18:10:49,756 INFO: Inventory1 startup [in C:\Users\1\inventory2\inventory1\app\__init__.py:42]
2020-08-11 18:10:53,708 ERROR: Exception on /api/login [POST] [in c:\users\1\inventory2\inventory1\venv\lib\site-packages\flask\app.py:1891]
Traceback (most recent call last):
  File "c:\users\1\inventory2\inventory1\venv\lib\site-packages\flask\app.py", line 2447, in wsgi_app
    response = self.full_dispatch_request()
  File "c:\users\1\inventory2\inventory1\venv\lib\site-packages\flask\app.py", line 1952, in full_dispatch_request
    rv = self.handle_user_exception(e)
  File "c:\users\1\inventory2\inventory1\venv\lib\site-packages\flask\app.py", line 1821, in handle_user_exception
    reraise(exc_type, exc_value, tb)
  File "c:\users\1\inventory2\inventory1\venv\lib\site-packages\flask\_compat.py", line 39, in reraise
    raise value
  File "c:\users\1\inventory2\inventory1\venv\lib\site-packages\flask\app.py", line 1950, in full_dispatch_request
    rv = self.dispatch_request()
  File "c:\users\1\inventory2\inventory1\venv\lib\site-packages\flask\app.py", line 1936, in dispatch_request
    return self.view_functions[rule.endpoint](**req.view_args)
  File "c:\users\1\inventory2\inventory1\venv\lib\site-packages\flask_cors\decorator.py", line 128, in wrapped_function
    resp = make_response(f(*args, **kwargs))
  File "c:\users\1\inventory2\inventory1\venv\lib\site-packages\flask_httpauth.py", line 148, in decorated
    user = self.authenticate(auth, password)
  File "c:\users\1\inventory2\inventory1\venv\lib\site-packages\flask_httpauth.py", line 219, in authenticate
    return self.verify_password_callback(username, client_password)
  File "C:\Users\1\inventory2\inventory1\app\api\auth.py", line 14, in verify_password
    workers = Worker.query.filter_by(login=login).first()
  File "c:\users\1\inventory2\inventory1\venv\lib\site-packages\flask_sqlalchemy\__init__.py", line 512, in __get__
    mapper = orm.class_mapper(type)
  File "c:\users\1\inventory2\inventory1\venv\lib\site-packages\sqlalchemy\orm\base.py", line 451, in class_mapper
    mapper = _inspect_mapped_class(class_, configure=configure)
  File "c:\users\1\inventory2\inventory1\venv\lib\site-packages\sqlalchemy\orm\base.py", line 430, in _inspect_mapped_class
    mapper._configure_all()
  File "c:\users\1\inventory2\inventory1\venv\lib\site-packages\sqlalchemy\orm\mapper.py", line 1354, in _configure_all
    configure_mappers()
  File "c:\users\1\inventory2\inventory1\venv\lib\site-packages\sqlalchemy\orm\mapper.py", line 3280, in configure_mappers
    mapper._post_configure_properties()
  File "c:\users\1\inventory2\inventory1\venv\lib\site-packages\sqlalchemy\orm\mapper.py", line 1967, in _post_configure_properties
    prop.init()
  File "c:\users\1\inventory2\inventory1\venv\lib\site-packages\sqlalchemy\orm\interfaces.py", line 197, in init
    self.do_init()
  File "c:\users\1\inventory2\inventory1\venv\lib\site-packages\sqlalchemy\orm\relationships.py", line 2080, in do_init
    self._generate_backref()
  File "c:\users\1\inventory2\inventory1\venv\lib\site-packages\sqlalchemy\orm\relationships.py", line 2329, in _generate_backref
    raise sa_exc.ArgumentError(
sqlalchemy.exc.ArgumentError: Error creating backref 'oid' on relationship 'Object.movements': property of that name exists on mapper 'mapped class Movement->movement'
2020-08-11 18:12:21,144 INFO: Inventory1 startup [in C:\Users\1\inventory2\inventory1\app\__init__.py:42]
2020-08-11 18:15:04,016 INFO: Inventory1 startup [in C:\Users\1\inventory2\inventory1\app\__init__.py:42]
2020-08-11 18:15:45,408 ERROR: Exception on /api/register [POST] [in c:\users\1\inventory2\inventory1\venv\lib\site-packages\flask\app.py:1891]
Traceback (most recent call last):
  File "c:\users\1\inventory2\inventory1\venv\lib\site-packages\flask\app.py", line 2447, in wsgi_app
    response = self.full_dispatch_request()
  File "c:\users\1\inventory2\inventory1\venv\lib\site-packages\flask\app.py", line 1952, in full_dispatch_request
    rv = self.handle_user_exception(e)
  File "c:\users\1\inventory2\inventory1\venv\lib\site-packages\flask\app.py", line 1821, in handle_user_exception
    reraise(exc_type, exc_value, tb)
  File "c:\users\1\inventory2\inventory1\venv\lib\site-packages\flask\_compat.py", line 39, in reraise
    raise value
  File "c:\users\1\inventory2\inventory1\venv\lib\site-packages\flask\app.py", line 1950, in full_dispatch_request
    rv = self.dispatch_request()
  File "c:\users\1\inventory2\inventory1\venv\lib\site-packages\flask\app.py", line 1936, in dispatch_request
    return self.view_functions[rule.endpoint](**req.view_args)
  File "c:\users\1\inventory2\inventory1\venv\lib\site-packages\flask_cors\decorator.py", line 128, in wrapped_function
    resp = make_response(f(*args, **kwargs))
  File "C:\Users\1\inventory2\inventory1\app\api\commodity.py", line 56, in register
    password = row['password']
TypeError: 'NoneType' object is not subscriptable
